Workbook

Sheet Indices Mines Exporting Ports
A1: Mine | B1: Date | C1: Total Alumina | D1: LT Avail. Alumina | E1: Total Silica | F1: LT R.Silica | G1: Quartz / HT Silica | H1: Mono-hydrate / HT Alumina | I1: Moisture | J1: Processing | K1: Processing Penalties to be applied | L1: DWT | M1: Specific Index | N1: General Index | O1: Exporting Port | P1: Handysize | Q1: Supramax loading rates | R1: Panamax loading rates | S1: NeoPanamax loading rate | T1: Suezmax loading rate | U1: Capesize loading rates | V1: VLOC loading rates | W1: Spare
A2: Guinea 45/3 LT | B2: 43466 | C2: 0.45 | D2: 0.41 | E2: 0.03 | F2: 0.016 | G2: 0.014 | H2: 0.024 | I2: 0.1 | J2: LT | K2: 0.33 | M2: Guinea 45/3 LT | N2: CBIX LT
A3: Australia HT | B3: 43466 | C3: 0.54 | D3: 0.3725 | E3: 0.09 | F3: 0.0675 | G3: 0.0225 | H3: 0.1 | I3: 0.125 | J3: HT-D | K3: 0.67 | M3: Australia HT | N3: CBIX HT
A4: Indonesian LT | B4: 43466 | C4: 0.48 | D4: 0.44 | E4: 0.08 | F4: 0.035 | G4: 0.045 | H4: 0.005 | I4: 0.15 | J4: LT | K4: 0.33 | M4: Indonesian LT | N4: CBIX LT
A5: CBIX LT | B5: 43466 | C5: 0.5 | D5: 0.45 | E5: 0.05 | F5: 0.05 | G5: 0 | H5: 0 | I5: 0.1 | J5: LT | K5: 0 | M5: CBIX LT | N5: CBIX LT
A6: CBIX HT | B6: 43466 | C6: 0.5 | D6: 0.45 | E6: 0.05 | F6: 0.05 | G6: 0 | H6: 0 | I6: 0.1 | J6: LT | K6: 0 | M6: CBIX HT | N6: CBIX HT
A7: CBIX | B7: 43466 | C7: 0.5 | D7: 0.45 | E7: 0.05 | F7: 0.05 | G7: 0 | H7: 0 | I7: 0.1 | J7: LT | K7: 0 | M7: CBIX | N7: CBIX
A8: SMB Generic | B8: 43466 | C8: 0.448 | D8: 0.4 | E8: 0.023 | F8: 0.013 | G8: 0.01 | H8: 0.035 | I8: 0.1 | J8: LT | K8: 0.33 | L8: 180000 | M8: Guinea 45/3 LT | N8: CBIX LT | O8: SMB-WAP_Nunez_Offshore | P8: 30000 | Q8: 30000 | R8: 30000 | S8: 30000 | T8: 30000 | U8: 30000 | V8: 30000
A9: Alufer Bel Air | B9: 43466 | C9: 0.46 | D9: 0.405 | E9: 0.048 | F9: 0.017 | G9: 0.031 | H9: 0.038 | I9: 0.101 | J9: LT | K9: 0.33 | L9: 180000 | M9: Guinea 45/3 LT | N9: CBIX LT | O9: Alufer_Cape_Verga_Offshore | P9: 18000 | Q9: 18000 | R9: 18000 | S9: 18000 | T9: 18000 | U9: 18000 | V9: 18000
A10: CBG LT | B10: 43466 | C10: 0.487 | D10: 0.433 | E10: 0.022 | F10: 0.019 | G10: 0.003 | H10: 0.035 | I10: 0.071 | J10: LT | K10: 0.33 | L10: 66000 | M10: Guinea 45/3 LT | N10: CBIX LT | O10: CBG_Wharf | P10: 30000 | Q10: 30000 | R10: 30000 | S10: 30000 | T10: 30000 | U10: 20000 | V10: 20000
A11: GAC Generic | B11: 43466 | C11: 0.47 | D11: 0.41 | E11: 0.02 | F11: 0.01 | G11: 0.01 | H11: 0.039 | I11: 0.088 | J11: LT | K11: 0.33 | L11: 180000 | M11: Guinea 45/3 LT | N11: CBIX LT | O11: GAC_Offshore | P11: 30000 | Q11: 30000 | R11: 30000 | S11: 30000 | T11: 30000 | U11: 30000 | V11: 30000
A12: Weipa/Amrun Generic | B12: 43466 | C12: 0.53 | D12: 0.3625 | E12: 0.09 | F12: 0.0675 | G12: 0.0225 | H12: 0.1 | I12: 0.13 | J12: HT-D | K12: 0.67 | L12: 76000 | M12: Australia HT | N12: CBIX HT | O12: Weipa_Amrun_Wharf | P12: 80000 | Q12: 80000 | R12: 80000 | S12: 80000 | T12: 80000 | U12: 40000 | V12: 40000
A13: West Kalimantan Generic | B13: 43466 | C13: 0.48 | D13: 0.44 | E13: 0.08 | F13: 0.035 | G13: 0.045 | H13: 0.005 | I13: 0.15 | J13: LT | K13: 0.33 | L13: 57000 | M13: Indonesian LT | N13: CBIX LT | O13: West_Kal_Generic_Offshore | P13: 15000 | Q13: 15000 | R13: 15000 | S13: 15000 | T13: 15000 | U13: 15000 | V13: 15000
A14: MRN | B14: 43466 | C14: 0.55 | D14: 0.49 | E14: 0.06 | F14: 0.055 | G14: 0.005 | H14: 0.005 | I14: 0.12 | J14: LT | K14: 0 | L14: 180000 | M14: CBIX LT | N14: CBIX LT | O14: Pt_Lisas | P14: 30000 | Q14: 30000 | R14: 30000 | S14: 30000 | T14: 30000 | U14: 30000 | V14: 30000
A15: Juruti | B15: 43466 | C15: 0.52 | D15: 0.475 | E15: 0.045 | F15: 0.041 | G15: 0.004 | H15: 0.004 | I15: 0.12 | J15: LT | K15: 0 | L15: 180000 | M15: CBIX LT | N15: CBIX LT | O15: Pt_Lisas | P15: 30000 | Q15: 30000 | R15: 30000 | S15: 30000 | T15: 30000 | U15: 30000 | V15: 30000
A16: MRN | B16: 43466 | C16: 0.55 | D16: 0.49 | E16: 0.06 | F16: 0.055 | G16: 0.005 | H16: 0.005 | I16: 0.12 | J16: LT | K16: 0 | L16: 57000 | M16: CBIX LT | N16: CBIX LT | O16: MRN_wharf | P16: 30000 | Q16: 30000 | R16: 30000 | S16: 30000 | T16: 30000 | U16: 30000 | V16: 30000
A17: Juruti | B17: 43466 | C17: 0.52 | D17: 0.475 | E17: 0.045 | F17: 0.041 | G17: 0.004 | H17: 0.004 | I17: 0.12 | J17: LT | K17: 0 | L17: 57000 | M17: CBIX LT | N17: CBIX LT | O17: Juruti_wharf | P17: 30000 | Q17: 30000 | R17: 30000 | S17: 30000 | T17: 30000 | U17: 30000 | V17: 30000
A18: Gove | B18: 43466 | C18: 0.495 | D18: 0.425 | E18: 0.05 | F18: 0.042 | G18: 0.008 | H18: 0.028 | I18: 0.095 | J18: LT | K18: 0.67 | L18: 95000 | M18: CBIX LT | N18: CBIX LT | O18: Gove_wharf | P18: 80000 | Q18: 80000 | R18: 80000 | S18: 80000 | T18: 80000 | U18: 40000 | V18: 40000
A19: Central Kalimantan Generic | B19: 43466 | C19: 0.48 | D19: 0.44 | E19: 0.08 | F19: 0.035 | G19: 0.045 | H19: 0.005 | I19: 0.15 | J19: LT | K19: 0.33 | L19: 57000 | M19: Indonesian LT | N19: CBIX LT | O19: Central_Kal_Generic_Offshore | P19: 15000 | Q19: 15000 | R19: 15000 | S19: 15000 | T19: 15000 | U19: 15000 | V19: 15000
... A31: Weipa/Amrun Generic | B31: 43994 | C31: 0.54 | D31: 0.3725 | E31: 0.09 | F31: 0.0675 | G31: 0.0225 | H31: 0.1 | I31: 0.125 | J31: HT-D | K31: 0.67 | L31: 76000 | M31: Australia HT | N31: CBIX HT | O31: Weipa_Amrun_Wharf | P31: 80000 | Q31: 80000 | R31: 80000 | S31: 80000 | T31: 80000 | U31: 40000 | V31: 40000

Sheet processing factors
A1: Date | B1: Processing Regime | C1: HT Alumina Dissolution | D1: DSP Al2O3:SiO2 (wt/wt) | E1: DSP NaOH:SiO2 (wt/wt) | F1: Lime rate (wt/wt_AA) | G1: Lig Coal (GJ/t) | H1: Quartz Attack | I1: Extraction Efficiency % | J1: Caustic wash loss (t.NaOH/t.aa) | K1: spare
A2: 43466 | B2: HT-D | C2: 1 | D2: 1.23 | E2: 0.6 | F2: 0.22 | G2: 13.5 | H2: 1 | I2: 0.9 | J2: 0.035
A3: 43466 | B3: HT-B | C3: 1 | D3: 1 | E3: 0.9 | F3: 0.036 | G3: 13.5 | H3: 0.5 | I3: 0.9 | J3: 0.035
A4: 43466 | B4: LT | C4: 0 | D4: 1 | E4: 0.9 | F4: 0.036 | G4: 12.15 | H4: 0 | I4: 0.9 | J4: 0.035

Sheet Lignitious Coal
A2: Date | B2: Lignitious Coal Price (RMB/t) (exc VAT) | C2: Energy value (kcal/kg)
A3: 40724 | B3: 632.47863 | C3: 4000
A4: 40755 | B4: 658.11966 | C4: 4000
A5: 40786 | B5: 658.11966 | C5: 4000
A6: 40816 | B6: 658.11966 | C6: 4000
A7: 40847 | B7: 658.11966 | C7: 4000
A8: 40877 | B8: 658.11966 | C8: 4000
A9: 40908 | B9: 658.11966 | C9: 4000
A10: 40939 | B10: 692.30769 | C10: 4000
A11: 40968 | B11: 685.79487 | C11: 4000
A12: 40999 | B12: 683.76068 | C12: 4000
A13: 41029 | B13: 683.76068 | C13: 4000
A14: 41060 | B14: 786.73504 | C14: 4000
... A102: 44008 | B102: 426 | C102: 4000

Sheet Caustic Soda
A1: Date | B1: Caustic Soda Price (RMB/t) (exc VAT) | C1: Grade
A2: 40724 | B2: 2386.1 | C2: 1
A3: 40755 | B3: 2365.4 | C3: 1
A4: 40786 | B4: 2257.8 | C4: 1
A5: 40816 | B5: 2402.8 | C5: 1
A6: 40847 | B6: 2498.5 | C6: 1
A7: 40877 | B7: 2636.1 | C7: 1
A8: 40908 | B8: 2700 | C8: 1
A9: 40939 | B9: 2640.5 | C9: 1
A10: 40968 | B10: 2494.6 | C10: 1
A11: 40999 | B11: 2256 | C11: 1
A12: 41029 | B12: 2593.9 | C12: 1
A13: 41060 | B13: 2698 | C13: 1
... A110: 43953 | B110: 1500 | C110: 1

Sheet Lime
A1: Date | B1: Lime Price (RMB/t)
A2: 40724 | B2: 300
A3: 41090 | B3: 300
A4: 41764 | B4: 340
A5: 42049 | B5: 240
A6: 42073 | B6: 240
A7: 42103 | B7: 240
A8: 42136 | B8: 240
A9: 42153 | B9: 240
A10: 42219 | B10: 240
A11: 42277 | B11: 241
A12: 42310 | B12: 240
A13: 42341 | B13: 240
... A27: 42882 | B27: 240

Sheet Mud disposal cost
A1: Date | B1: Mud disposal cost Price (RMB/t.mud dry)
A2: 40724 | B2: 20
A3: 41090 | B3: 20
A4: 41764 | B4: 22
A5: 43253 | B5: 30

Sheet Global factors
A1: Date | B1: kcal per GJ | C1: conversion kt to t | D1: hours per day | E1: legs per round trip | F1: shipping profit rate | G1: Alumina mol weight | H1: Silica Mol Wt | I1: Kaolinite (Al2O3.2SiO2.2H20) - Al2O3:SiO2 ratio | J1: Max % of vessel deadweight allowed for loading | K1: LOA estimate correlation multiplier | L1: LOA estimate correlation constant | M1: NRT estimate correlation multiplier | N1: NRT estimate correlation constant | O1: GRT estimate correlation multiplier | P1: GRT estimate correlation constant | Q1: Minimum Lay days allowed | R1: Minimum Lay days allowed as % of sailing time | S1: Lay allowance Loading port | T1: Extra time tie up + untie at each port | U1: MDO/MGO burn vessel DWT denominator | V1: MDO/MGO burn vessel DWT slope | W1: MDO/MGO burn vessel DWT constant | X1: Main engine burn vessel DWT denominator | Y1: Main engine burn vessel DWT exponent | Z1: Main engine burn speed linear coefficient | AA1: Main engine burn speed ^2 coefficient | AB1: Main engine burn speed ^3 coefficient | AC1: Main engine burn overall correction factor | AD1: Reference Port | AE1: Freight Insurance Rate | AF1: Freight Commission
A2: 43466 | B2: 239000 | C2: 1000 | D2: 24 | E2: 2 | F2: 0.08 | G2: 101.96 | H2: 60.08 | I2: 0.84853529 | J2: 0.975 | K2: 0.000873 | L2: 145.89 | M2: 0.4034 | N2: 0 | O2: 0.5189 | P2: 4797 | Q2: 7 | R2: 0.12 | S2: 0.5 | T2: 0.5 | U2: 10000 | V2: 0.1068 | W2: 1.2 | X2: 23643.709 | Y2: 0.6280287 | Z2: 0 | AA2: 0.062556362 | AB2: 0.00086923129 | AC2: 1.15 | AD2: Qingdao | AE2: 0.003 | AF2: 0.05

Sheet Ship Time Charter Rates
A1: Date | B1: Vesssel class | C1: Applicable Time Charter Index | D1: Vessel Time Charter Rates
A2: 43483 | B2: Capesize | C2: Capesize_General | D2: 14050
A3: 43483 | B3: Panamax | C3: Panamax_General | D3: 9777
A4: 43483 | B4: Supramax | C4: Supramax_General | D4: 8850
A5: 43483 | B5: Handysize | C5: Handysize_General | D5: 8850
A6: 43483 | B6: Panamax | C6: P3A_03 | D6: 9777
A7: 43490 | B7: Capesize | C7: Capesize_General | D7: 12725
A8: 43490 | B8: Panamax | C8: Panamax_General | D8: 9312
A9: 43490 | B9: Supramax | C9: Supramax_General | D9: 8786
A10: 43490 | B10: Handysize | C10: Handysize_General | D10: 8786
A11: 43490 | B11: Panamax | C11: P3A_03 | D11: 9312
A12: 43497 | B12: Capesize | C12: Capesize_General | D12: 11979
A13: 43497 | B13: Panamax | C13: Panamax_General | D13: 8319
... A381: 44008 | B381: Panamax | C381: P3A_03 | D381: 9770.8

Sheet Ship Speeds
A1: Date | B1: Vesssel class | C1: Vessel Cruising speed
A2: 43466 | B2: VLOC | C2: 11.25
A3: 43466 | B3: Capesize | C3: 11.25
A4: 43466 | B4: Panamax | C4: 11.25
A5: 43466 | B5: Supramax | C5: 11.25
A6: 43466 | B6: Handysize | C6: 11.25
A7: 43973 | B7: VLOC | C7: 11
A8: 43973 | B8: Capesize | C8: 11
A9: 43973 | B9: Panamax | C9: 11
A10: 43973 | B10: Supramax | C10: 11
A11: 43973 | B11: Handysize | C11: 11

Sheet Trade Details
A1: Date | B1: CM Data Source | C1: Mine | D1: Price | E1: Price Type | F1: Price Basis | G1: Total Alumina | H1: LT Avail. Alumina | I1: Total Silica | J1: LT R.Silica | K1: Quartz / HT Silica | L1: Mono-hydrate / HT Extble Alumina | M1: Moisture | N1: Tonnage | O1: Exporting Port | P1: Importing Port | Q1: Final Specs Price Type | R1: Final Specs Price Basis | S1: Old CBIX type Calc
A2: 43525 | B2: Mysteel | C2: SMB Generic | D2: 55 | E2: CIF | F2: dmt | N2: 153450 | P2: Qingdao | Q2: CIF | R2: dmt | S2: CBIX
A3: 43530 | B3: Mysteel | C3: West Kalimantan Generic | D3: 54 | E3: CIF | F3: dmt | N3: 174396 | P3: Qingdao | Q3: CIF | R3: dmt | S3: CBIX
A4: 43531 | B4: Mysteel | C4: Weipa/Amrun Generic | D4: 49 | E4: CIF | F4: dmt | N4: 74154 | P4: Qingdao | Q4: CIF | R4: dmt | S4: CBIX
A5: 43923 | B5: somebody | C5: Gove | D5: 50 | E5: CFR | F5: dmt | P5: Qingdao | Q5: CFR | R5: dmt | S5: CBIX
A6: 43923 | B6: somebody | C6: Alufer Bel Air | D6: 50 | E6: CFR | F6: dmt | P6: Qingdao | Q6: CFR | R6: dmt | S6: CBIX
A7: 43923 | B7: somebody | C7: Central Kalimantan Generic | D7: 50 | E7: CFR | F7: dmt | P7: Qingdao | Q7: CFR | R7: dmt | S7: CBIX
A8: 43923 | B8: somebody | C8: CBG LT | D8: 50 | E8: CFR | F8: dmt | P8: Qingdao | Q8: CFR | R8: dmt | S8: CBIX
A9: 43923 | B9: somebody | C9: Huntly | D9: 50 | E9: CFR | F9: dmt | P9: Qingdao | Q9: CFR | R9: dmt | S9: CBIX
A10: 43923 | B10: somebody | C10: Turkey | D10: 100 | E10: CFR | F10: dmt | P10: Qingdao | Q10: CFR | R10: dmt | S10: CBIX
A11: 43923 | B11: somebody | C11: Bauxite Hills | D11: 50 | E11: CFR | F11: dmt | P11: Qingdao | Q11: CFR | R11: dmt | S11: CBIX
A12: 43923 | B12: somebody | C12: Chalco Boffa | D12: 50 | E12: CFR | F12: dmt | P12: Qingdao | Q12: CFR | R12: dmt | S12: CBIX
A13: 43923 | B13: somebody | C13: Rennell Island | D13: 50 | E13: CFR | F13: dmt | P13: Qingdao | Q13: CFR | R13: dmt | S13: CBIX
A14: 43923 | B14: somebody | C14: Discovery Bay | D14: 50 | E14: CFR | F14: dmt | P14: Qingdao | Q14: CFR | R14: dmt | S14: CBIX
A15: 43923 | B15: somebody | C15: MRN | D15: 50 | E15: CFR | F15: dmt | N15: 140000 | P15: Qingdao | Q15: CFR | R15: dmt | S15: CBIX

Sheet Special 2 Leg Shipping Table
A1: Date | B1: Mine | C1: First Leg 1 | D1: First Leg 2 | E1: Typical River Capable Cargo (dmt)
A2: 43466 | B2: MRN | C2: MRN_wharf | D2: Pt_Lisas | E2: 48000
A3: 43466 | B3: Juruti | C3: Juruti_wharf | D3: Pt_Lisas | E3: 48000

Sheet MRN or Juruti max cargo
A1: MRN/Juruti max cargo single leg shipping
A2: 65000

Sheet FX Rates
A1: Date | B1: RMB per US$ | C1: AU$ per US$ | D1: US$ per US$ | E1: IMF Special Drawing Rights to US Dollar
A2: 40724 | B2: 6.47336 | C2: 1.05426 | D2: 1 | E2: 1.35
A3: 40731 | B3: 6.46778 | C3: 1.07156 | D3: 1 | E3: 1.35
A4: 40738 | B4: 6.4706 | C4: 1.0694 | D4: 1 | E4: 1.35
A5: 40745 | B5: 6.46498 | C5: 1.06744 | D5: 1 | E5: 1.35
A6: 40752 | B6: 6.44664 | C6: 1.09406 | D6: 1 | E6: 1.35
A7: 40759 | B7: 6.44174 | C7: 1.082 | D7: 1 | E7: 1.35
A8: 40766 | B8: 6.42498 | C8: 1.0315 | D8: 1 | E8: 1.35
A9: 40773 | B9: 6.3957 | C9: 1.04362 | D9: 1 | E9: 1.35
A10: 40780 | B10: 6.39616 | C10: 1.0422 | D10: 1 | E10: 1.35
A11: 40787 | B11: 6.388325 | C11: 1.0636 | D11: 1 | E11: 1.35
A12: 40794 | B12: 6.39408 | C12: 1.05982 | D12: 1 | E12: 1.35
A13: 40801 | B13: 6.39485 | C13: 1.03452 | D13: 1 | E13: 1.35
... A468: 44008 | B468: 7.06402 | C468: 0.687539 | D468: 1 | E468: 1.37746

Sheet China Price Series
A1: Lignitious Coal – Date | B1: Lignitious Coal – Price | C1: Lignitious Coal – Energy value | D1: Caustic Soda – Date | E1: Caustic Soda – Price | F1: Caustic Soda – Grade | G1: Lime – Date | H1: Lime – Price | I1: Mud disposal cost - Date | J1: Mud disposal cost – Price
A2: 40724 | B2: 632.47863 | C2: 4000 | D2: 40724 | E2: 2386.1 | F2: 1 | G2: 40724 | H2: 300 | I2: 40724 | J2: 20
A3: 40755 | B3: 658.11966 | C3: 4000 | D3: 40755 | E3: 2365.4 | F3: 1 | G3: 41090 | H3: 300 | I3: 41090 | J3: 20
A4: 40786 | B4: 658.11966 | C4: 4000 | D4: 40786 | E4: 2257.8 | F4: 1 | G4: 41764 | H4: 340 | I4: 41764 | J4: 22
A5: 40816 | B5: 658.11966 | C5: 4000 | D5: 40816 | E5: 2402.8 | F5: 1 | G5: 42049 | H5: 240 | I5: 43253 | J5: 30
A6: 40847 | B6: 658.11966 | C6: 4000 | D6: 40847 | E6: 2498.5 | F6: 1 | G6: 42073 | H6: 240
A7: 40877 | B7: 658.11966 | C7: 4000 | D7: 40877 | E7: 2636.1 | F7: 1 | G7: 42103 | H7: 240
A8: 40908 | B8: 658.11966 | C8: 4000 | D8: 40908 | E8: 2700 | F8: 1 | G8: 42136 | H8: 240
A9: 40939 | B9: 692.30769 | C9: 4000 | D9: 40939 | E9: 2640.5 | F9: 1 | G9: 42153 | H9: 240
A10: 40968 | B10: 685.79487 | C10: 4000 | D10: 40968 | E10: 2494.6 | F10: 1 | G10: 42219 | H10: 240
A11: 40999 | B11: 683.76068 | C11: 4000 | D11: 40999 | E11: 2256 | F11: 1 | G11: 42277 | H11: 241
A12: 41029 | B12: 683.76068 | C12: 4000 | D12: 41029 | E12: 2593.9 | F12: 1 | G12: 42310 | H12: 240
A13: 41060 | B13: 786.73504 | C13: 4000 | D13: 41060 | E13: 2698 | F13: 1 | G13: 42341 | H13: 240
A14: 41090 | B14: 676.06838 | C14: 4000 | D14: 41090 | E14: 2729.1 | F14: 1 | G14: 42373 | H14: 240
A15: 41121 | B15: 658.11966 | C15: 4000 | D15: 41121 | E15: 2812.8 | F15: 1 | G15: 42406 | H15: 240
A16: 41152 | B16: 610.55556 | C16: 4000 | D16: 41152 | E16: 2828.6 | F16: 1 | G16: 42433 | H16: 240
A17: 41182 | B17: 384.61538 | C17: 4000 | D17: 41182 | E17: 2800 | F17: 1 | G17: 42584 | H17: 240
... A27: 41486 | B27: 393.16239 | C27: 4000 | D27: 41486 | E27: 1902.7 | F27: 1 | G27: 42882 | H27: 240
A28: 41517 | B28: 393.16239 | C28: 4000 | D28: 41517 | E28: 1825.8 | F28: 1
A29: 41552 | B29: 393 | C29: 4000 | D29: 41552 | E29: 1753 | F29: 1
A30: 41587 | B30: 393 | C30: 4000 | D30: 41587 | E30: 1844 | F30: 1
A31: 41610 | B31: 393 | C31: 4000 | D31: 41610 | E31: 1950 | F31: 1
A32: 41678 | B32: 393 | C32: 4000 | D32: 41678 | E32: 2112.8 | F32: 1
A33: 41707 | B33: 460 | C33: 4000 | D33: 41707 | E33: 2112.8 | F33: 1
A34: 41726 | B34: 393 | C34: 4000 | D34: 41726 | E34: 1795.9 | F34: 1
A35: 41764 | B35: 376 | C35: 4000 | D35: 41764 | E35: 1769 | F35: 1
A36: 41841 | B36: 385 | C36: 4000 | D36: 41841 | E36: 1600 | F36: 1
A37: 41883 | B37: 355 | C37: 4000 | D37: 41883 | E37: 1595 | F37: 1
A38: 41909 | B38: 355 | C38: 4000 | D38: 41909 | E38: 1635 | F38: 1
A39: 41944 | B39: 355 | C39: 4000 | D39: 41944 | E39: 1756 | F39: 1
... A93: 43645 | B93: 491 | C93: 4000 | D93: 43722 | E93: 2500 | F93: 1
D94: 43764 | E94: 2450 | F94: 1
D95: 43771 | E95: 2250 | F95: 1
D96: 43778 | E96: 2230 | F96: 1
D97: 43785 | E97: 2200 | F97: 1
D98: 43806 | E98: 2100 | F98: 1
D99: 43819 | E99: 1900 | F99: 1
D100: 43834 | E100: 1850 | F100: 1
D101: 43843 | E101: 1850 | F101: 1
D102: 43847 | E102: 1850 | F102: 1
...

Sheet Sheetname_Class
A1: DWT< tonnes | B1: Class
A2: 0 | B2: Handysize
A3: 40000 | B3: Supramax
A4: 60000 | B4: Panamax
A5: 100000 | B5: Capesize
A6: 220000 | B6: VLOC

Sheet Canals_Class
A1: DWT< tonnes | B1: Class
A2: 0 | B2: Handysize
A3: 40000 | B3: Supramax
A4: 60000 | B4: Panamax
A5: 100000 | B5: NeoPanamax
A6: 120000 | B6: Suezmax
A7: 190000 | B7: Capesize
A8: 220000 | B8: VLOC

Sheet Port Linkages
A1: Date | B1: Typical Mine | C1: Exporting Port | D1: Importing Port | E1: VLOC – Distance using Main Engine Fuel | F1: VLOC – Distance using Auxiliary Fuel | G1: VLOC – Applicable Time Charter Index | H1: VLOC – Applicable Fuel Region | I1: VLOC – Main Engine Fuel | J1: VLOC – Auxiliary Fuel | K1: VLOC – Canals used | L1: Capesize – Distance using Main Engine Fuel | M1: Capesize – Distance using Auxiliary Fuel | N1: Capesize – Applicable Time Charter Index | O1: Capesize – Applicable Fuel Region | P1: Capesize – Main Engine Fuel | Q1: Capesize – Auxiliary Fuel | R1: Capesize – Canals used | S1: Suezmax – Distance using Main Engine Fuel | T1: Suezmax – Distance using Auxiliary Fuel | U1: Suezmax – Applicable Time Charter Index | V1: Suezmax – Applicable Fuel Region | W1: Suezmax – Main Engine Fuel | X1: Suezmax – Auxiliary Fuel | Y1: Suezmax – Canals used | Z1: NeoPanamax – Distance using Main Engine Fuel | AA1: NeoPanamax – Distance using Auxiliary Fuel | AB1: NeoPanamax – Applicable Time Charter Index | AC1: NeoPanamax – Applicable Fuel Region | AD1: NeoPanamax – Main Engine Fuel | AE1: NeoPanamax – Auxiliary Fuel | AF1: NeoPanamax – Canals used | AG1: Panamax – Distance using Main Engine Fuel | AH1: Panamax – Distance using Auxiliary Fuel | AI1: Panamax – Applicable Time Charter Index | AJ1: Panamax – Applicable Fuel Region | AK1: Panamax – Main Engine Fuel | AL1: Panamax – Auxiliary Fuel | AM1: Panamax – Canals used | AN1: Supramax – Distance using Main Engine Fuel | AO1: Supramax – Distance using Auxiliary Fuel | AP1: Supramax – Applicable Time Charter Index | AQ1: Supramax – Applicable Fuel Region | AR1: Supramax – Main Engine Fuel | AS1: Supramax – Auxiliary Fuel | AT1: Supramax – Canals used | AU1: Handysize – Distance using Main Engine Fuel | AV1: Handysize – Distance using Auxiliary Fuel | AW1: Handysize – Applicable Time Charter Index | AX1: Handysize – Applicable Fuel Region | AY1: Handysize – Main Engine Fuel | AZ1: Handysize – Auxiliary Fuel | BA1: Handysize – Canals used
A2: 43466 | B2: =INDEX('[1]Indices Mines Exporting Ports'!$C$26:$C$51,MATCH(C2,'[1]Indices Mines Exporting Ports'!$Q$26:$Q$51,0)) -> MRN | C2: MRN_wharf | D2: Qingdao | E2: #N/A | F2: 0 | G2: Capesize_General | H2: Singapore | I2: HSFO | J2: MGO_Regular | K2: none | L2: #N/A | M2: 0 | N2: Capesize_General | O2: Singapore | P2: HSFO | Q2: MGO_Regular | R2: none | S2: #N/A | T2: 0 | U2: Capesize_General | V2: Singapore | W2: HSFO | X2: MGO_Regular | Y2: none | Z2: #N/A | AA2: 0 | AB2: Capesize_General | AC2: Singapore | AD2: HSFO | AE2: MGO_Regular | AF2: none | AG2: 11184 | AH2: 0 | AI2: Panamax_General | AJ2: Singapore | AK2: HSFO | AL2: MGO_Regular | AM2: Panamar | AN2: 11184 | AO2: 0 | AP2: Supramax_General | AQ2: Singapore | AR2: HSFO | AS2: MGO_Regular | AT2: Panamar | AU2: 11184 | AV2: 0 | AW2: Handysize_General | AX2: Singapore | AY2: HSFO | AZ2: MGO_Regular | BA2: Panamar
A3: 43466 | B3: =INDEX('[1]Indices Mines Exporting Ports'!$C$26:$C$51,MATCH(C3,'[1]Indices Mines Exporting Ports'!$Q$26:$Q$51,0)) -> MRN | C3: MRN_wharf | D3: Pt_Lisas | E3: #N/A | F3: 0 | G3: Capesize_General | H3: Singapore | I3: HSFO | J3: MGO_Regular | K3: none | L3: #N/A | M3: 0 | N3: Capesize_General | O3: Singapore | P3: HSFO | Q3: MGO_Regular | R3: none | S3: #N/A | T3: 0 | U3: Capesize_General | V3: Singapore | W3: HSFO | X3: MGO_Regular | Y3: none | Z3: #N/A | AA3: 0 | AB3: Capesize_General | AC3: Singapore | AD3: HSFO | AE3: MGO_Regular | AF3: none | AG3: 1623 | AH3: 0 | AI3: Panamax_General | AJ3: Singapore | AK3: HSFO | AL3: MGO_Regular | AM3: none | AN3: 1632 | AO3: 0 | AP3: Supramax_General | AQ3: Singapore | AR3: HSFO | AS3: MGO_Regular | AT3: none | AU3: 1632 | AV3: 0 | AW3: Handysize_General | AX3: Singapore | AY3: HSFO | AZ3: MGO_Regular | BA3: none
A4: 43466 | B4: =INDEX('[1]Indices Mines Exporting Ports'!$C$26:$C$51,MATCH(C4,'[1]Indices Mines Exporting Ports'!$Q$26:$Q$51,0)) -> MRN | C4: Pt_Lisas | D4: Qingdao | E4: 13157 | F4: 0 | G4: Capesize_General | H4: Singapore | I4: HSFO | J4: MGO_Regular | K4: none | L4: 13157 | M4: 0 | N4: Capesize_General | O4: Singapore | P4: HSFO | Q4: MGO_Regular | R4: none | S4: 13157 | T4: 0 | U4: Capesize_General | V4: Singapore | W4: HSFO | X4: MGO_Regular | Y4: none | Z4: #N/A | AA4: 0 | AB4: Capesize_General | AC4: Singapore | AD4: HSFO | AE4: MGO_Regular | AF4: none | AG4: #N/A | AH4: 0 | AI4: Panamax_General | AJ4: Singapore | AK4: HSFO | AL4: MGO_Regular | AM4: none | AN4: #N/A | AO4: 0 | AP4: Supramax_General | AQ4: Singapore | AR4: HSFO | AS4: MGO_Regular | AT4: none | AU4: #N/A | AV4: 0 | AW4: Handysize_General | AX4: Singapore | AY4: HSFO | AZ4: MGO_Regular | BA4: none
A5: 43466 | B5: =INDEX('[1]Indices Mines Exporting Ports'!$C$26:$C$51,MATCH(C5,'[1]Indices Mines Exporting Ports'!$Q$26:$Q$51,0)) -> Juruti | C5: Juruti_wharf | D5: Qingdao | E5: #N/A | F5: 0 | G5: Capesize_General | H5: Singapore | I5: HSFO | J5: MGO_Regular | K5: none | L5: #N/A | M5: 0 | N5: Capesize_General | O5: Singapore | P5: HSFO | Q5: MGO_Regular | R5: none | S5: #N/A | T5: 0 | U5: Capesize_General | V5: Singapore | W5: HSFO | X5: MGO_Regular | Y5: none | Z5: #N/A | AA5: 0 | AB5: Capesize_General | AC5: Singapore | AD5: HSFO | AE5: MGO_Regular | AF5: none | AG5: 11153 | AH5: 0 | AI5: Panamax_General | AJ5: Singapore | AK5: HSFO | AL5: MGO_Regular | AM5: Panamar | AN5: 11153 | AO5: 0 | AP5: Supramax_General | AQ5: Singapore | AR5: HSFO | AS5: MGO_Regular | AT5: Panamar | AU5: 11153 | AV5: 0 | AW5: Handysize_General | AX5: Singapore | AY5: HSFO | AZ5: MGO_Regular | BA5: Panamar
A6: 43466 | B6: =INDEX('[1]Indices Mines Exporting Ports'!$C$26:$C$51,MATCH(C6,'[1]Indices Mines Exporting Ports'!$Q$26:$Q$51,0)) -> Juruti | C6: Juruti_wharf | D6: Pt_Lisas | E6: #N/A | F6: 0 | G6: Capesize_General | H6: Singapore | I6: HSFO | J6: MGO_Regular | K6: none | L6: #N/A | M6: 0 | N6: Capesize_General | O6: Singapore | P6: HSFO | Q6: MGO_Regular | R6: none | S6: #N/A | T6: 0 | U6: Capesize_General | V6: Singapore | W6: HSFO | X6: MGO_Regular | Y6: none | Z6: #N/A | AA6: 0 | AB6: Capesize_General | AC6: Singapore | AD6: HSFO | AE6: MGO_Regular | AF6: none | AG6: 1601 | AH6: 0 | AI6: Panamax_General | AJ6: Singapore | AK6: HSFO | AL6: MGO_Regular | AM6: none | AN6: 1601 | AO6: 0 | AP6: Supramax_General | AQ6: Singapore | AR6: HSFO | AS6: MGO_Regular | AT6: none | AU6: 1601 | AV6: 0 | AW6: Handysize_General | AX6: Singapore | AY6: HSFO | AZ6: MGO_Regular | BA6: none
A7: 43466 | B7: =INDEX('[1]Indices Mines Exporting Ports'!$C$26:$C$51,MATCH(C7,'[1]Indices Mines Exporting Ports'!$Q$26:$Q$51,0)) -> SMB Generic | C7: SMB-WAP_Nunez_Offshore | D7: Qingdao | E7: 11150 | F7: 0 | G7: Capesize_General | H7: Singapore | I7: HSFO | J7: MGO_Regular | K7: none | L7: 11150 | M7: 0 | N7: Capesize_General | O7: Singapore | P7: HSFO | Q7: MGO_Regular | R7: none | S7: 11150 | T7: 0 | U7: Capesize_General | V7: Singapore | W7: HSFO | X7: MGO_Regular | Y7: none | Z7: 11150 | AA7: 0 | AB7: Capesize_General | AC7: Singapore | AD7: HSFO | AE7: MGO_Regular | AF7: none | AG7: 11150 | AH7: 0 | AI7: Panamax_General | AJ7: Singapore | AK7: HSFO | AL7: MGO_Regular | AM7: none | AN7: 11150 | AO7: 0 | AP7: Supramax_General | AQ7: Singapore | AR7: HSFO | AS7: MGO_Regular | AT7: none | AU7: 11150 | AV7: 0 | AW7: Handysize_General | AX7: Singapore | AY7: HSFO | AZ7: MGO_Regular | BA7: none
A8: 43466 | B8: =INDEX('[1]Indices Mines Exporting Ports'!$C$26:$C$51,MATCH(C8,'[1]Indices Mines Exporting Ports'!$Q$26:$Q$51,0)) -> Alufer Bel Air | C8: Alufer_Cape_Verga_Offshore | D8: Qingdao | E8: 11100 | F8: 0 | G8: Capesize_General | H8: Singapore | I8: HSFO | J8: MGO_Regular | K8: none | L8: 11100 | M8: 0 | N8: Capesize_General | O8: Singapore | P8: HSFO | Q8: MGO_Regular | R8: none | S8: 11100 | T8: 0 | U8: Capesize_General | V8: Singapore | W8: HSFO | X8: MGO_Regular | Y8: none | Z8: 11100 | AA8: 0 | AB8: Capesize_General | AC8: Singapore | AD8: HSFO | AE8: MGO_Regular | AF8: none | AG8: 11100 | AH8: 0 | AI8: Panamax_General | AJ8: Singapore | AK8: HSFO | AL8: MGO_Regular | AM8: none | AN8: 11100 | AO8: 0 | AP8: Supramax_General | AQ8: Singapore | AR8: HSFO | AS8: MGO_Regular | AT8: none | AU8: 11100 | AV8: 0 | AW8: Handysize_General | AX8: Singapore | AY8: HSFO | AZ8: MGO_Regular | BA8: none
A9: 43466 | B9: =INDEX('[1]Indices Mines Exporting Ports'!$C$26:$C$51,MATCH(C9,'[1]Indices Mines Exporting Ports'!$Q$26:$Q$51,0)) -> CBG LT | C9: CBG_Wharf | D9: Qingdao | E9: 11170 | F9: 0 | G9: Capesize_General | H9: Singapore | I9: HSFO | J9: MGO_Regular | K9: none | L9: 11170 | M9: 0 | N9: Capesize_General | O9: Singapore | P9: HSFO | Q9: MGO_Regular | R9: none | S9: 11170 | T9: 0 | U9: Capesize_General | V9: Singapore | W9: HSFO | X9: MGO_Regular | Y9: none | Z9: 11170 | AA9: 0 | AB9: Capesize_General | AC9: Singapore | AD9: HSFO | AE9: MGO_Regular | AF9: none | AG9: 11170 | AH9: 0 | AI9: Panamax_General | AJ9: Singapore | AK9: HSFO | AL9: MGO_Regular | AM9: none | AN9: 11170 | AO9: 0 | AP9: Supramax_General | AQ9: Singapore | AR9: HSFO | AS9: MGO_Regular | AT9: none | AU9: 11170 | AV9: 0 | AW9: Handysize_General | AX9: Singapore | AY9: HSFO | AZ9: MGO_Regular | BA9: none
A10: 43466 | B10: =INDEX('[1]Indices Mines Exporting Ports'!$C$26:$C$51,MATCH(C10,'[1]Indices Mines Exporting Ports'!$Q$26:$Q$51,0)) -> GAC Generic | C10: GAC_Offshore | D10: Qingdao | E10: 11150 | F10: 0 | G10: Capesize_General | H10: Singapore | I10: HSFO | J10: MGO_Regular | K10: none | L10: 11150 | M10: 0 | N10: Capesize_General | O10: Singapore | P10: HSFO | Q10: MGO_Regular | R10: none | S10: 11150 | T10: 0 | U10: Capesize_General | V10: Singapore | W10: HSFO | X10: MGO_Regular | Y10: none | Z10: 11150 | AA10: 0 | AB10: Capesize_General | AC10: Singapore | AD10: HSFO | AE10: MGO_Regular | AF10: none | AG10: 11150 | AH10: 0 | AI10: Panamax_General | AJ10: Singapore | AK10: HSFO | AL10: MGO_Regular | AM10: none | AN10: 11150 | AO10: 0 | AP10: Supramax_General | AQ10: Singapore | AR10: HSFO | AS10: MGO_Regular | AT10: none | AU10: 11150 | AV10: 0 | AW10: Handysize_General | AX10: Singapore | AY10: HSFO | AZ10: MGO_Regular | BA10: none
A11: 43466 | B11: =INDEX('[1]Indices Mines Exporting Ports'!$C$26:$C$51,MATCH(C11,'[1]Indices Mines Exporting Ports'!$Q$26:$Q$51,0)) -> Weipa/Amrun Generic | C11: Weipa_Amrun_Wharf | D11: Qingdao | E11: 3280 | F11: 0 | G11: Capesize_General | H11: Singapore | I11: HSFO | J11: MGO_Regular | K11: none | L11: 3280 | M11: 0 | N11: Capesize_General | O11: Singapore | P11: HSFO | Q11: MGO_Regular | R11: none | S11: 3280 | T11: 0 | U11: Capesize_General | V11: Singapore | W11: HSFO | X11: MGO_Regular | Y11: none | Z11: 3280 | AA11: 0 | AB11: Capesize_General | AC11: Singapore | AD11: HSFO | AE11: MGO_Regular | AF11: none | AG11: 3280 | AH11: 0 | AI11: Panamax_General | AJ11: Singapore | AK11: HSFO | AL11: MGO_Regular | AM11: none | AN11: 3280 | AO11: 0 | AP11: Supramax_General | AQ11: Singapore | AR11: HSFO | AS11: MGO_Regular | AT11: none | AU11: 3280 | AV11: 0 | AW11: Handysize_General | AX11: Singapore | AY11: HSFO | AZ11: MGO_Regular | BA11: none
A12: 43466 | B12: =INDEX('[1]Indices Mines Exporting Ports'!$C$26:$C$51,MATCH(C12,'[1]Indices Mines Exporting Ports'!$Q$26:$Q$51,0)) -> West Kalimantan Generic | C12: West_Kal_Generic_Offshore | D12: Qingdao | E12: 2326 | F12: 0 | G12: Capesize_General | H12: Singapore | I12: HSFO | J12: MGO_Regular | K12: none | L12: 2326 | M12: 0 | N12: Capesize_General | O12: Singapore | P12: HSFO | Q12: MGO_Regular | R12: none | S12: 2326 | T12: 0 | U12: Capesize_General | V12: Singapore | W12: HSFO | X12: MGO_Regular | Y12: none | Z12: 2326 | AA12: 0 | AB12: Capesize_General | AC12: Singapore | AD12: HSFO | AE12: MGO_Regular | AF12: none | AG12: 2326 | AH12: 0 | AI12: Panamax_General | AJ12: Singapore | AK12: HSFO | AL12: MGO_Regular | AM12: none | AN12: 2326 | AO12: 0 | AP12: Supramax_General | AQ12: Singapore | AR12: HSFO | AS12: MGO_Regular | AT12: none | AU12: 2326 | AV12: 0 | AW12: Handysize_General | AX12: Singapore | AY12: HSFO | AZ12: MGO_Regular | BA12: none
A13: 43466 | B13: =INDEX('[1]Indices Mines Exporting Ports'!$C$26:$C$51,MATCH(C13,'[1]Indices Mines Exporting Ports'!$Q$26:$Q$51,0)) -> Gove | C13: Gove_wharf | D13: Qingdao | E13: #N/A | F13: 0 | G13: Capesize_General | H13: Singapore | I13: HSFO | J13: MGO_Regular | K13: none | L13: #N/A | M13: 0 | N13: Capesize_General | O13: Singapore | P13: HSFO | Q13: MGO_Regular | R13: none | S13: #N/A | T13: 0 | U13: Capesize_General | V13: Singapore | W13: HSFO | X13: MGO_Regular | Y13: none | Z13: 3079 | AA13: 0 | AB13: Capesize_General | AC13: Singapore | AD13: HSFO | AE13: MGO_Regular | AF13: none | AG13: 3079 | AH13: 0 | AI13: Panamax_General | AJ13: Singapore | AK13: HSFO | AL13: MGO_Regular | AM13: none | AN13: 3079 | AO13: 0 | AP13: Supramax_General | AQ13: Singapore | AR13: HSFO | AS13: MGO_Regular | AT13: none | AU13: 3079 | AV13: 0 | AW13: Handysize_General | AX13: Singapore | AY13: HSFO | AZ13: MGO_Regular | BA13: none
A14: 43466 | B14: =INDEX('[1]Indices Mines Exporting Ports'!$C$26:$C$51,MATCH(C14,'[1]Indices Mines Exporting Ports'!$Q$26:$Q$51,0)) -> Central Kalimantan Generic | C14: Central_Kal_Generic_Offshore | D14: Qingdao | E14: 2300 | F14: 0 | G14: Capesize_General | H14: Singapore | I14: HSFO | J14: MGO_Regular | K14: none | L14: 2300 | M14: 0 | N14: Capesize_General | O14: Singapore | P14: HSFO | Q14: MGO_Regular | R14: none | S14: 2300 | T14: 0 | U14: Capesize_General | V14: Singapore | W14: HSFO | X14: MGO_Regular | Y14: none | Z14: 2300 | AA14: 0 | AB14: Capesize_General | AC14: Singapore | AD14: HSFO | AE14: MGO_Regular | AF14: none | AG14: 2300 | AH14: 0 | AI14: Panamax_General | AJ14: Singapore | AK14: HSFO | AL14: MGO_Regular | AM14: none | AN14: 2300 | AO14: 0 | AP14: Supramax_General | AQ14: Singapore | AR14: HSFO | AS14: MGO_Regular | AT14: none | AU14: 2300 | AV14: 0 | AW14: Handysize_General | AX14: Singapore | AY14: HSFO | AZ14: MGO_Regular | BA14: none
A15: 43466 | B15: =INDEX('[1]Indices Mines Exporting Ports'!$C$26:$C$51,MATCH(C15,'[1]Indices Mines Exporting Ports'!$Q$26:$Q$51,0)) -> Huntly | C15: Kwinana_wharf | D15: Qingdao | E15: #N/A | F15: 0 | G15: Capesize_General | H15: Singapore | I15: HSFO | J15: MGO_Regular | K15: none | L15: #N/A | M15: 0 | N15: Capesize_General | O15: Singapore | P15: HSFO | Q15: MGO_Regular | R15: none | S15: #N/A | T15: 0 | U15: Capesize_General | V15: Singapore | W15: HSFO | X15: MGO_Regular | Y15: none | Z15: #N/A | AA15: 0 | AB15: Capesize_General | AC15: Singapore | AD15: HSFO | AE15: MGO_Regular | AF15: none | AG15: 4250 | AH15: 0 | AI15: Panamax_General | AJ15: Singapore | AK15: HSFO | AL15: MGO_Regular | AM15: none | AN15: 4250 | AO15: 0 | AP15: Supramax_General | AQ15: Singapore | AR15: HSFO | AS15: MGO_Regular | AT15: none | AU15: 4250 | AV15: 0 | AW15: Handysize_General | AX15: Singapore | AY15: HSFO | AZ15: MGO_Regular | BA15: none
A16: 43466 | B16: =INDEX('[1]Indices Mines Exporting Ports'!$C$26:$C$51,MATCH(C16,'[1]Indices Mines Exporting Ports'!$Q$26:$Q$51,0)) -> Turkey | C16: Turkey | D16: Qingdao | E16: 14562 | F16: 0 | G16: Capesize_General | H16: Singapore | I16: HSFO | J16: MGO_Regular | K16: none | L16: 14562 | M16: 0 | N16: Capesize_General | O16: Singapore | P16: HSFO | Q16: MGO_Regular | R16: none | S16: 8426 | T16: 0 | U16: Capesize_General | V16: Singapore | W16: HSFO | X16: MGO_Regular | Y16: Suez | Z16: 8426 | AA16: 0 | AB16: Capesize_General | AC16: Singapore | AD16: HSFO | AE16: MGO_Regular | AF16: Suez | AG16: 8426 | AH16: 0 | AI16: Panamax_General | AJ16: Singapore | AK16: HSFO | AL16: MGO_Regular | AM16: Suez | AN16: 8426 | AO16: 0 | AP16: Supramax_General | AQ16: Singapore | AR16: HSFO | AS16: MGO_Regular | AT16: Suez | AU16: 8426 | AV16: 0 | AW16: Handysize_General | AX16: Singapore | AY16: HSFO | AZ16: MGO_Regular | BA16: Suez
A17: 43466 | B17: =INDEX('[1]Indices Mines Exporting Ports'!$C$26:$C$51,MATCH(C17,'[1]Indices Mines Exporting Ports'!$Q$26:$Q$51,0)) -> Bauxite Hills | C17: Bauxite_Hills_offshore | D17: Qingdao | E17: 3270 | F17: 0 | G17: Capesize_General | H17: Singapore | I17: HSFO | J17: MGO_Regular | K17: none | L17: 3270 | M17: 0 | N17: Capesize_General | O17: Singapore | P17: HSFO | Q17: MGO_Regular | R17: none | S17: 3270 | T17: 0 | U17: Capesize_General | V17: Singapore | W17: HSFO | X17: MGO_Regular | Y17: Suez | Z17: 3270 | AA17: 0 | AB17: Capesize_General | AC17: Singapore | AD17: HSFO | AE17: MGO_Regular | AF17: Suez | AG17: 3270 | AH17: 0 | AI17: Panamax_General | AJ17: Singapore | AK17: HSFO | AL17: MGO_Regular | AM17: Suez | AN17: 3270 | AO17: 0 | AP17: Supramax_General | AQ17: Singapore | AR17: HSFO | AS17: MGO_Regular | AT17: Suez | AU17: 3270 | AV17: 0 | AW17: Handysize_General | AX17: Singapore | AY17: HSFO | AZ17: MGO_Regular | BA17: Suez
A18: 43466 | B18: =INDEX('[1]Indices Mines Exporting Ports'!$C$26:$C$51,MATCH(C18,'[1]Indices Mines Exporting Ports'!$Q$26:$Q$51,0)) -> Chalco Boffa | C18: Chalco_Boffa_offshore | D18: Qingdao | E18: 11050 | F18: 0 | G18: Capesize_General | H18: Singapore | I18: HSFO | J18: MGO_Regular | K18: none | L18: 11050 | M18: 0 | N18: Capesize_General | O18: Singapore | P18: HSFO | Q18: MGO_Regular | R18: none | S18: 11050 | T18: 0 | U18: Capesize_General | V18: Singapore | W18: HSFO | X18: MGO_Regular | Y18: none | Z18: 11050 | AA18: 0 | AB18: Capesize_General | AC18: Singapore | AD18: HSFO | AE18: MGO_Regular | AF18: none | AG18: 11050 | AH18: 0 | AI18: Panamax_General | AJ18: Singapore | AK18: HSFO | AL18: MGO_Regular | AM18: none | AN18: 11050 | AO18: 0 | AP18: Supramax_General | AQ18: Singapore | AR18: HSFO | AS18: MGO_Regular | AT18: none | AU18: 11050 | AV18: 0 | AW18: Handysize_General | AX18: Singapore | AY18: HSFO | AZ18: MGO_Regular | BA18: none
A19: 43466 | B19: =INDEX('[1]Indices Mines Exporting Ports'!$C$26:$C$51,MATCH(C19,'[1]Indices Mines Exporting Ports'!$Q$26:$Q$51,0)) -> Rennell Island | C19: Rennell_Is._offshore | D19: Qingdao | E19: 3542 | F19: 0 | G19: Capesize_General | H19: Singapore | I19: HSFO | J19: MGO_Regular | K19: none | L19: 3542 | M19: 0 | N19: Capesize_General | O19: Singapore | P19: HSFO | Q19: MGO_Regular | R19: none | S19: 3542 | T19: 0 | U19: Capesize_General | V19: Singapore | W19: HSFO | X19: MGO_Regular | Y19: none | Z19: 3542 | AA19: 0 | AB19: Capesize_General | AC19: Singapore | AD19: HSFO | AE19: MGO_Regular | AF19: none | AG19: 3542 | AH19: 0 | AI19: Panamax_General | AJ19: Singapore | AK19: HSFO | AL19: MGO_Regular | AM19: none | AN19: 3542 | AO19: 0 | AP19: Supramax_General | AQ19: Singapore | AR19: HSFO | AS19: MGO_Regular | AT19: none | AU19: 3542 | AV19: 0 | AW19: Handysize_General | AX19: Singapore | AY19: HSFO | AZ19: MGO_Regular | BA19: none
A20: 43466 | B20: =INDEX('[1]Indices Mines Exporting Ports'!$C$26:$C$51,MATCH(C20,'[1]Indices Mines Exporting Ports'!$Q$26:$Q$51,0)) -> Discovery Bay | C20: Discovery_Bay_wharf | D20: Qingdao | E20: 14116 | F20: 0 | G20: Capesize_General | H20: Singapore | I20: HSFO | J20: MGO_Regular | K20: none | L20: 14116 | M20: 0 | N20: Capesize_General | O20: Singapore | P20: HSFO | Q20: MGO_Regular | R20: none | S20: 14116 | T20: 0 | U20: Capesize_General | V20: Singapore | W20: HSFO | X20: MGO_Regular | Y20: none | Z20: 9156 | AA20: 0 | AB20: Capesize_General | AC20: Singapore | AD20: HSFO | AE20: MGO_Regular | AF20: NeoPanamar | AG20: 9156 | AH20: 0 | AI20: Panamax_General | AJ20: Singapore | AK20: HSFO | AL20: MGO_Regular | AM20: Panamar | AN20: 9156 | AO20: 0 | AP20: Supramax_General | AQ20: Singapore | AR20: HSFO | AS20: MGO_Regular | AT20: Panamar | AU20: 9156 | AV20: 0 | AW20: Handysize_General | AX20: Singapore | AY20: HSFO | AZ20: MGO_Regular | BA20: Panamar
A21: 43466 | B21: =INDEX('[1]Indices Mines Exporting Ports'!$C$26:$C$51,MATCH(C21,'[1]Indices Mines Exporting Ports'!$Q$26:$Q$51,0)) -> Turkey | C21: Turkey | D21: Qingdao | E21: 14562 | F21: 0 | G21: Capesize_General | H21: Singapore | I21: HSFO | J21: MGO_Regular | K21: none | L21: 14562 | M21: 0 | N21: Capesize_General | O21: Singapore | P21: HSFO | Q21: MGO_Regular | R21: none | S21: 8426 | T21: 0 | U21: Capesize_General | V21: Singapore | W21: HSFO | X21: MGO_Regular | Y21: Suez | Z21: 8426 | AA21: 0 | AB21: Capesize_General | AC21: Singapore | AD21: HSFO | AE21: MGO_Regular | AF21: Suez | AG21: 8426 | AH21: 0 | AI21: Panamax_General | AJ21: Singapore | AK21: HSFO | AL21: MGO_Regular | AM21: Suez | AN21: 8426 | AO21: 0 | AP21: Supramax_General | AQ21: Singapore | AR21: HSFO | AS21: MGO_Regular | AT21: Suez | AU21: 8426 | AV21: 0 | AW21: Handysize_General | AX21: Singapore | AY21: HSFO | AZ21: MGO_Regular | BA21: Suez
A22: 43466 | B22: =INDEX('[1]Indices Mines Exporting Ports'!$C$26:$C$51,MATCH(C22,'[1]Indices Mines Exporting Ports'!$Q$26:$Q$51,0)) -> West Kalimantan Generic | C22: West_Kal_Generic_Offshore | D22: Qingdao | E22: 2326 | F22: 0 | G22: Capesize_General | H22: Singapore | I22: HSFO | J22: MGO_Regular | K22: none | L22: 2326 | M22: 0 | N22: Capesize_General | O22: Singapore | P22: HSFO | Q22: MGO_Regular | R22: none | S22: 2326 | T22: 0 | U22: Capesize_General | V22: Singapore | W22: HSFO | X22: MGO_Regular | Y22: none | Z22: 2326 | AA22: 0 | AB22: Capesize_General | AC22: Singapore | AD22: HSFO | AE22: MGO_Regular | AF22: none | AG22: 2326 | AH22: 0 | AI22: Panamax_General | AJ22: Singapore | AK22: HSFO | AL22: MGO_Regular | AM22: none | AN22: 2326 | AO22: 0 | AP22: Supramax_General | AQ22: Singapore | AR22: HSFO | AS22: MGO_Regular | AT22: none | AU22: 2326 | AV22: 0 | AW22: Handysize_General | AX22: Singapore | AY22: HSFO | AZ22: MGO_Regular | BA22: none
A23: 43466 | B23: =INDEX('[1]Indices Mines Exporting Ports'!$C$26:$C$51,MATCH(C23,'[1]Indices Mines Exporting Ports'!$Q$26:$Q$51,0)) -> Chalco Boffa | C23: Chalco_Boffa_offshore | D23: Qingdao | E23: 11050 | F23: 0 | G23: Capesize_General | H23: Singapore | I23: HSFO | J23: MGO_Regular | K23: none | L23: 11050 | M23: 0 | N23: Capesize_General | O23: Singapore | P23: HSFO | Q23: MGO_Regular | R23: none | S23: 11050 | T23: 0 | U23: Capesize_General | V23: Singapore | W23: HSFO | X23: MGO_Regular | Y23: none | Z23: 11050 | AA23: 0 | AB23: Capesize_General | AC23: Singapore | AD23: HSFO | AE23: MGO_Regular | AF23: none | AG23: 11050 | AH23: 0 | AI23: Panamax_General | AJ23: Singapore | AK23: HSFO | AL23: MGO_Regular | AM23: none | AN23: 11050 | AO23: 0 | AP23: Supramax_General | AQ23: Singapore | AR23: HSFO | AS23: MGO_Regular | AT23: none | AU23: 11050 | AV23: 0 | AW23: Handysize_General | AX23: Singapore | AY23: HSFO | AZ23: MGO_Regular | BA23: none
A24: 43466 | B24: =INDEX('[1]Indices Mines Exporting Ports'!$C$26:$C$51,MATCH(C24,'[1]Indices Mines Exporting Ports'!$Q$26:$Q$51,0)) -> SMB Generic | C24: SMB-WAP_Nunez_Offshore | D24: UAE | E24: 6612 | F24: 0 | G24: Capesize_General | H24: Singapore | I24: HSFO | J24: MGO_Regular | K24: none | L24: 6612 | M24: 0 | N24: Capesize_General | O24: Singapore | P24: HSFO | Q24: MGO_Regular | R24: none | S24: 6612 | T24: 0 | U24: Capesize_General | V24: Singapore | W24: HSFO | X24: MGO_Regular | Y24: Suez | Z24: 6612 | AA24: 0 | AB24: Capesize_General | AC24: Singapore | AD24: HSFO | AE24: MGO_Regular | AF24: Suez | AG24: 6612 | AH24: 0 | AI24: Panamax_General | AJ24: Singapore | AK24: HSFO | AL24: MGO_Regular | AM24: Suez | AN24: 6612 | AO24: 0 | AP24: Supramax_General | AQ24: Singapore | AR24: HSFO | AS24: MGO_Regular | AT24: Suez | AU24: 6612 | AV24: 0 | AW24: Handysize_General | AX24: Singapore | AY24: HSFO | AZ24: MGO_Regular | BA24: Suez
A25: 43466 | B25: =INDEX('[1]Indices Mines Exporting Ports'!$C$26:$C$51,MATCH(C25,'[1]Indices Mines Exporting Ports'!$Q$26:$Q$51,0)) -> CBG LT | C25: CBG_Wharf | D25: Aughinish | E25: 2791 | F25: 0 | G25: Capesize_General | H25: Singapore | I25: HSFO | J25: MGO_Regular | K25: none | L25: 2791 | M25: 0 | N25: Capesize_General | O25: Singapore | P25: HSFO | Q25: MGO_Regular | R25: none | S25: 2791 | T25: 0 | U25: Capesize_General | V25: Singapore | W25: HSFO | X25: MGO_Regular | Y25: none | Z25: 2791 | AA25: 0 | AB25: Capesize_General | AC25: Singapore | AD25: HSFO | AE25: MGO_Regular | AF25: none | AG25: 2791 | AH25: 0 | AI25: Panamax_General | AJ25: Singapore | AK25: HSFO | AL25: MGO_Regular | AM25: none | AN25: 2791 | AO25: 0 | AP25: Supramax_General | AQ25: Singapore | AR25: HSFO | AS25: MGO_Regular | AT25: none | AU25: 2791 | AV25: 0 | AW25: Handysize_General | AX25: Singapore | AY25: HSFO | AZ25: MGO_Regular | BA25: none
A26: 43466 | B26: =INDEX('[1]Indices Mines Exporting Ports'!$C$26:$C$51,MATCH(C26,'[1]Indices Mines Exporting Ports'!$Q$26:$Q$51,0)) -> CBG LT | C26: CBG_Wharf | D26: Ukraine | E26: 4161 | F26: 0 | G26: Capesize_General | H26: Singapore | I26: HSFO | J26: MGO_Regular | K26: none | L26: 4161 | M26: 0 | N26: Capesize_General | O26: Singapore | P26: HSFO | Q26: MGO_Regular | R26: none | S26: 4161 | T26: 0 | U26: Capesize_General | V26: Singapore | W26: HSFO | X26: MGO_Regular | Y26: none | Z26: 4161 | AA26: 0 | AB26: Capesize_General | AC26: Singapore | AD26: HSFO | AE26: MGO_Regular | AF26: none | AG26: 4161 | AH26: 0 | AI26: Panamax_General | AJ26: Singapore | AK26: HSFO | AL26: MGO_Regular | AM26: none | AN26: 4161 | AO26: 0 | AP26: Supramax_General | AQ26: Singapore | AR26: HSFO | AS26: MGO_Regular | AT26: none | AU26: 4161 | AV26: 0 | AW26: Handysize_General | AX26: Singapore | AY26: HSFO | AZ26: MGO_Regular | BA26: none
A27: 43466 | B27: =INDEX('[1]Indices Mines Exporting Ports'!$C$26:$C$51,MATCH(C27,'[1]Indices Mines Exporting Ports'!$Q$26:$Q$51,0)) -> SMB Generic | C27: SMB-WAP_Nunez_Offshore | D27: Visakhapatnam | E27: 8382 | F27: 0 | G27: Capesize_General | H27: Singapore | I27: HSFO | J27: MGO_Regular | K27: none | L27: 8382 | M27: 0 | N27: Capesize_General | O27: Singapore | P27: HSFO | Q27: MGO_Regular | R27: none | S27: 8382 | T27: 0 | U27: Capesize_General | V27: Singapore | W27: HSFO | X27: MGO_Regular | Y27: none | Z27: 8382 | AA27: 0 | AB27: Capesize_General | AC27: Singapore | AD27: HSFO | AE27: MGO_Regular | AF27: none | AG27: 8382 | AH27: 0 | AI27: Panamax_General | AJ27: Singapore | AK27: HSFO | AL27: MGO_Regular | AM27: none | AN27: 8382 | AO27: 0 | AP27: Supramax_General | AQ27: Singapore | AR27: HSFO | AS27: MGO_Regular | AT27: none | AU27: 8382 | AV27: 0 | AW27: Handysize_General | AX27: Singapore | AY27: HSFO | AZ27: MGO_Regular | BA27: none
A28: 43466 | B28: =INDEX('[1]Indices Mines Exporting Ports'!$C$26:$C$51,MATCH(C28,'[1]Indices Mines Exporting Ports'!$Q$26:$Q$51,0)) -> Gujarat & Maharashtra | C28: Sikka | D28: Qingdao | E28: 5345 | F28: 0 | G28: Capesize_General | H28: Singapore | I28: HSFO | J28: MGO_Regular | K28: none | L28: 5345 | M28: 0 | N28: Capesize_General | O28: Singapore | P28: HSFO | Q28: MGO_Regular | R28: none | S28: 5345 | T28: 0 | U28: Capesize_General | V28: Singapore | W28: HSFO | X28: MGO_Regular | Y28: none | Z28: 5345 | AA28: 0 | AB28: Capesize_General | AC28: Singapore | AD28: HSFO | AE28: MGO_Regular | AF28: none | AG28: 5345 | AH28: 0 | AI28: Panamax_General | AJ28: Singapore | AK28: HSFO | AL28: MGO_Regular | AM28: none | AN28: 5345 | AO28: 0 | AP28: Supramax_General | AQ28: Singapore | AR28: HSFO | AS28: MGO_Regular | AT28: none | AU28: 5345 | AV28: 0 | AW28: Handysize_General | AX28: Singapore | AY28: HSFO | AZ28: MGO_Regular | BA28: none
A29: 43831 | B29: =INDEX('[1]Indices Mines Exporting Ports'!$C$26:$C$51,MATCH(C29,'[1]Indices Mines Exporting Ports'!$Q$26:$Q$51,0)) -> MRN | C29: MRN_wharf | D29: Qingdao | E29: #N/A | F29: 0 | G29: Capesize_General | H29: Singapore | I29: VLSFO | J29: MGO_Regular | K29: none | L29: #N/A | M29: 0 | N29: Capesize_General | O29: Singapore | P29: VLSFO | Q29: MGO_Regular | R29: none | S29: #N/A | T29: 0 | U29: Capesize_General | V29: Singapore | W29: VLSFO | X29: MGO_Regular | Y29: none | Z29: #N/A | AA29: 0 | AB29: Capesize_General | AC29: Singapore | AD29: VLSFO | AE29: MGO_Regular | AF29: none | AG29: 11184 | AH29: 0 | AI29: Panamax_General | AJ29: Singapore | AK29: VLSFO | AL29: MGO_Regular | AM29: Panamar | AN29: 11184 | AO29: 0 | AP29: Supramax_General | AQ29: Singapore | AR29: VLSFO | AS29: MGO_Regular | AT29: Panamar | AU29: 11184 | AV29: 0 | AW29: Handysize_General | AX29: Singapore | AY29: VLSFO | AZ29: MGO_Regular | BA29: Panamar
A30: 43831 | B30: =INDEX('[1]Indices Mines Exporting Ports'!$C$26:$C$51,MATCH(C30,'[1]Indices Mines Exporting Ports'!$Q$26:$Q$51,0)) -> MRN | C30: MRN_wharf | D30: Pt_Lisas | E30: #N/A | F30: 0 | G30: Capesize_General | H30: Singapore | I30: VLSFO | J30: MGO_Regular | K30: none | L30: #N/A | M30: 0 | N30: Capesize_General | O30: Singapore | P30: VLSFO | Q30: MGO_Regular | R30: none | S30: #N/A | T30: 0 | U30: Capesize_General | V30: Singapore | W30: VLSFO | X30: MGO_Regular | Y30: none | Z30: #N/A | AA30: 0 | AB30: Capesize_General | AC30: Singapore | AD30: VLSFO | AE30: MGO_Regular | AF30: none | AG30: 1623 | AH30: 0 | AI30: Panamax_General | AJ30: Singapore | AK30: VLSFO | AL30: MGO_Regular | AM30: none | AN30: 1632 | AO30: 0 | AP30: Supramax_General | AQ30: Singapore | AR30: VLSFO | AS30: MGO_Regular | AT30: none | AU30: 1632 | AV30: 0 | AW30: Handysize_General | AX30: Singapore | AY30: VLSFO | AZ30: MGO_Regular | BA30: none
A31: 43831 | B31: =INDEX('[1]Indices Mines Exporting Ports'!$C$26:$C$51,MATCH(C31,'[1]Indices Mines Exporting Ports'!$Q$26:$Q$51,0)) -> MRN | C31: Pt_Lisas | D31: Qingdao | E31: 13157 | F31: 0 | G31: Capesize_General | H31: Singapore | I31: VLSFO | J31: MGO_Regular | K31: none | L31: 13157 | M31: 0 | N31: Capesize_General | O31: Singapore | P31: VLSFO | Q31: MGO_Regular | R31: none | S31: 13157 | T31: 0 | U31: Capesize_General | V31: Singapore | W31: VLSFO | X31: MGO_Regular | Y31: none | Z31: #N/A | AA31: 0 | AB31: Capesize_General | AC31: Singapore | AD31: VLSFO | AE31: MGO_Regular | AF31: none | AG31: #N/A | AH31: 0 | AI31: Panamax_General | AJ31: Singapore | AK31: VLSFO | AL31: MGO_Regular | AM31: none | AN31: #N/A | AO31: 0 | AP31: Supramax_General | AQ31: Singapore | AR31: VLSFO | AS31: MGO_Regular | AT31: none | AU31: #N/A | AV31: 0 | AW31: Handysize_General | AX31: Singapore | AY31: VLSFO | AZ31: MGO_Regular | BA31: none
A32: 43831 | B32: =INDEX('[1]Indices Mines Exporting Ports'!$C$26:$C$51,MATCH(C32,'[1]Indices Mines Exporting Ports'!$Q$26:$Q$51,0)) -> Juruti | C32: Juruti_wharf | D32: Qingdao | E32: #N/A | F32: 0 | G32: Capesize_General | H32: Singapore | I32: VLSFO | J32: MGO_Regular | K32: none | L32: #N/A | M32: 0 | N32: Capesize_General | O32: Singapore | P32: VLSFO | Q32: MGO_Regular | R32: none | S32: #N/A | T32: 0 | U32: Capesize_General | V32: Singapore | W32: VLSFO | X32: MGO_Regular | Y32: none | Z32: #N/A | AA32: 0 | AB32: Capesize_General | AC32: Singapore | AD32: VLSFO | AE32: MGO_Regular | AF32: none | AG32: 11153 | AH32: 0 | AI32: Panamax_General | AJ32: Singapore | AK32: VLSFO | AL32: MGO_Regular | AM32: Panamar | AN32: 11153 | AO32: 0 | AP32: Supramax_General | AQ32: Singapore | AR32: VLSFO | AS32: MGO_Regular | AT32: Panamar | AU32: 11153 | AV32: 0 | AW32: Handysize_General | AX32: Singapore | AY32: VLSFO | AZ32: MGO_Regular | BA32: Panamar
A33: 43831 | B33: =INDEX('[1]Indices Mines Exporting Ports'!$C$26:$C$51,MATCH(C33,'[1]Indices Mines Exporting Ports'!$Q$26:$Q$51,0)) -> Juruti | C33: Juruti_wharf | D33: Pt_Lisas | E33: #N/A | F33: 0 | G33: Capesize_General | H33: Singapore | I33: VLSFO | J33: MGO_Regular | K33: none | L33: #N/A | M33: 0 | N33: Capesize_General | O33: Singapore | P33: VLSFO | Q33: MGO_Regular | R33: none | S33: #N/A | T33: 0 | U33: Capesize_General | V33: Singapore | W33: VLSFO | X33: MGO_Regular | Y33: none | Z33: #N/A | AA33: 0 | AB33: Capesize_General | AC33: Singapore | AD33: VLSFO | AE33: MGO_Regular | AF33: none | AG33: 1601 | AH33: 0 | AI33: Panamax_General | AJ33: Singapore | AK33: VLSFO | AL33: MGO_Regular | AM33: none | AN33: 1601 | AO33: 0 | AP33: Supramax_General | AQ33: Singapore | AR33: VLSFO | AS33: MGO_Regular | AT33: none | AU33: 1601 | AV33: 0 | AW33: Handysize_General | AX33: Singapore | AY33: VLSFO | AZ33: MGO_Regular | BA33: none
A34: 43831 | B34: =INDEX('[1]Indices Mines Exporting Ports'!$C$26:$C$51,MATCH(C34,'[1]Indices Mines Exporting Ports'!$Q$26:$Q$51,0)) -> SMB Generic | C34: SMB-WAP_Nunez_Offshore | D34: Qingdao | E34: 11150 | F34: 0 | G34: Capesize_General | H34: Singapore | I34: VLSFO | J34: MGO_Regular | K34: none | L34: 11150 | M34: 0 | N34: Capesize_General | O34: Singapore | P34: VLSFO | Q34: MGO_Regular | R34: none | S34: 11150 | T34: 0 | U34: Capesize_General | V34: Singapore | W34: VLSFO | X34: MGO_Regular | Y34: none | Z34: 11150 | AA34: 0 | AB34: Capesize_General | AC34: Singapore | AD34: VLSFO | AE34: MGO_Regular | AF34: none | AG34: 11150 | AH34: 0 | AI34: Panamax_General | AJ34: Singapore | AK34: VLSFO | AL34: MGO_Regular | AM34: none | AN34: 11150 | AO34: 0 | AP34: Supramax_General | AQ34: Singapore | AR34: VLSFO | AS34: MGO_Regular | AT34: none | AU34: 11150 | AV34: 0 | AW34: Handysize_General | AX34: Singapore | AY34: VLSFO | AZ34: MGO_Regular | BA34: none
A35: 43831 | B35: =INDEX('[1]Indices Mines Exporting Ports'!$C$26:$C$51,MATCH(C35,'[1]Indices Mines Exporting Ports'!$Q$26:$Q$51,0)) -> Alufer Bel Air | C35: Alufer_Cape_Verga_Offshore | D35: Qingdao | E35: 11100 | F35: 0 | G35: Capesize_General | H35: Singapore | I35: VLSFO | J35: MGO_Regular | K35: none | L35: 11100 | M35: 0 | N35: Capesize_General | O35: Singapore | P35: VLSFO | Q35: MGO_Regular | R35: none | S35: 11100 | T35: 0 | U35: Capesize_General | V35: Singapore | W35: VLSFO | X35: MGO_Regular | Y35: none | Z35: 11100 | AA35: 0 | AB35: Capesize_General | AC35: Singapore | AD35: VLSFO | AE35: MGO_Regular | AF35: none | AG35: 11100 | AH35: 0 | AI35: Panamax_General | AJ35: Singapore | AK35: VLSFO | AL35: MGO_Regular | AM35: none | AN35: 11100 | AO35: 0 | AP35: Supramax_General | AQ35: Singapore | AR35: VLSFO | AS35: MGO_Regular | AT35: none | AU35: 11100 | AV35: 0 | AW35: Handysize_General | AX35: Singapore | AY35: VLSFO | AZ35: MGO_Regular | BA35: none
A36: 43831 | B36: =INDEX('[1]Indices Mines Exporting Ports'!$C$26:$C$51,MATCH(C36,'[1]Indices Mines Exporting Ports'!$Q$26:$Q$51,0)) -> CBG LT | C36: CBG_Wharf | D36: Qingdao | E36: 11170 | F36: 0 | G36: Capesize_General | H36: Singapore | I36: VLSFO | J36: MGO_Regular | K36: none | L36: 11170 | M36: 0 | N36: Capesize_General | O36: Singapore | P36: VLSFO | Q36: MGO_Regular | R36: none | S36: 11170 | T36: 0 | U36: Capesize_General | V36: Singapore | W36: VLSFO | X36: MGO_Regular | Y36: none | Z36: 11170 | AA36: 0 | AB36: Capesize_General | AC36: Singapore | AD36: VLSFO | AE36: MGO_Regular | AF36: none | AG36: 11170 | AH36: 0 | AI36: Panamax_General | AJ36: Singapore | AK36: VLSFO | AL36: MGO_Regular | AM36: none | AN36: 11170 | AO36: 0 | AP36: Supramax_General | AQ36: Singapore | AR36: VLSFO | AS36: MGO_Regular | AT36: none | AU36: 11170 | AV36: 0 | AW36: Handysize_General | AX36: Singapore | AY36: VLSFO | AZ36: MGO_Regular | BA36: none
A37: 43831 | B37: =INDEX('[1]Indices Mines Exporting Ports'!$C$26:$C$51,MATCH(C37,'[1]Indices Mines Exporting Ports'!$Q$26:$Q$51,0)) -> GAC Generic | C37: GAC_Offshore | D37: Qingdao | E37: 11150 | F37: 0 | G37: Capesize_General | H37: Singapore | I37: VLSFO | J37: MGO_Regular | K37: none | L37: 11150 | M37: 0 | N37: Capesize_General | O37: Singapore | P37: VLSFO | Q37: MGO_Regular | R37: none | S37: 11150 | T37: 0 | U37: Capesize_General | V37: Singapore | W37: VLSFO | X37: MGO_Regular | Y37: none | Z37: 11150 | AA37: 0 | AB37: Capesize_General | AC37: Singapore | AD37: VLSFO | AE37: MGO_Regular | AF37: none | AG37: 11150 | AH37: 0 | AI37: Panamax_General | AJ37: Singapore | AK37: VLSFO | AL37: MGO_Regular | AM37: none | AN37: 11150 | AO37: 0 | AP37: Supramax_General | AQ37: Singapore | AR37: VLSFO | AS37: MGO_Regular | AT37: none | AU37: 11150 | AV37: 0 | AW37: Handysize_General | AX37: Singapore | AY37: VLSFO | AZ37: MGO_Regular | BA37: none
A38: 43831 | B38: =INDEX('[1]Indices Mines Exporting Ports'!$C$26:$C$51,MATCH(C38,'[1]Indices Mines Exporting Ports'!$Q$26:$Q$51,0)) -> Weipa/Amrun Generic | C38: Weipa_Amrun_Wharf | D38: Qingdao | E38: 3280 | F38: 0 | G38: Capesize_General | H38: Singapore | I38: VLSFO | J38: MGO_Regular | K38: none | L38: 3280 | M38: 0 | N38: Capesize_General | O38: Singapore | P38: VLSFO | Q38: MGO_Regular | R38: none | S38: 3280 | T38: 0 | U38: Capesize_General | V38: Singapore | W38: VLSFO | X38: MGO_Regular | Y38: none | Z38: 3280 | AA38: 0 | AB38: Capesize_General | AC38: Singapore | AD38: VLSFO | AE38: MGO_Regular | AF38: none | AG38: 3280 | AH38: 0 | AI38: Panamax_General | AJ38: Singapore | AK38: VLSFO | AL38: MGO_Regular | AM38: none | AN38: 3280 | AO38: 0 | AP38: Supramax_General | AQ38: Singapore | AR38: VLSFO | AS38: MGO_Regular | AT38: none | AU38: 3280 | AV38: 0 | AW38: Handysize_General | AX38: Singapore | AY38: VLSFO | AZ38: MGO_Regular | BA38: none
A39: 43831 | B39: =INDEX('[1]Indices Mines Exporting Ports'!$C$26:$C$51,MATCH(C39,'[1]Indices Mines Exporting Ports'!$Q$26:$Q$51,0)) -> West Kalimantan Generic | C39: West_Kal_Generic_Offshore | D39: Qingdao | E39: 2326 | F39: 0 | G39: Capesize_General | H39: Singapore | I39: VLSFO | J39: MGO_Regular | K39: none | L39: 2326 | M39: 0 | N39: Capesize_General | O39: Singapore | P39: VLSFO | Q39: MGO_Regular | R39: none | S39: 2326 | T39: 0 | U39: Capesize_General | V39: Singapore | W39: VLSFO | X39: MGO_Regular | Y39: none | Z39: 2326 | AA39: 0 | AB39: Capesize_General | AC39: Singapore | AD39: VLSFO | AE39: MGO_Regular | AF39: none | AG39: 2326 | AH39: 0 | AI39: Panamax_General | AJ39: Singapore | AK39: VLSFO | AL39: MGO_Regular | AM39: none | AN39: 2326 | AO39: 0 | AP39: Supramax_General | AQ39: Singapore | AR39: VLSFO | AS39: MGO_Regular | AT39: none | AU39: 2326 | AV39: 0 | AW39: Handysize_General | AX39: Singapore | AY39: VLSFO | AZ39: MGO_Regular | BA39: none
A40: 43831 | B40: =INDEX('[1]Indices Mines Exporting Ports'!$C$26:$C$51,MATCH(C40,'[1]Indices Mines Exporting Ports'!$Q$26:$Q$51,0)) -> Gove | C40: Gove_wharf | D40: Qingdao | E40: #N/A | F40: 0 | G40: Capesize_General | H40: Singapore | I40: VLSFO | J40: MGO_Regular | K40: none | L40: #N/A | M40: 0 | N40: Capesize_General | O40: Singapore | P40: VLSFO | Q40: MGO_Regular | R40: none | S40: #N/A | T40: 0 | U40: Capesize_General | V40: Singapore | W40: VLSFO | X40: MGO_Regular | Y40: none | Z40: 3079 | AA40: 0 | AB40: Capesize_General | AC40: Singapore | AD40: VLSFO | AE40: MGO_Regular | AF40: none | AG40: 3079 | AH40: 0 | AI40: Panamax_General | AJ40: Singapore | AK40: VLSFO | AL40: MGO_Regular | AM40: none | AN40: 3079 | AO40: 0 | AP40: Supramax_General | AQ40: Singapore | AR40: VLSFO | AS40: MGO_Regular | AT40: none | AU40: 3079 | AV40: 0 | AW40: Handysize_General | AX40: Singapore | AY40: VLSFO | AZ40: MGO_Regular | BA40: none
...

Sheet Ship Fuel Prices
A1: Date | B1: Fuel Region | C1: HSFO(180 / 380) | D1: VLSFO | E1: LNG | F1: MDO/MGO Regular | G1: MDO/MGO Low Sulphur
A2: 40724 | B2: Singapore | C2: 637.15 | F2: 894
A3: 40731 | B3: Singapore | C3: 650 | F3: 912.8
A4: 40738 | B4: Singapore | C4: 666.2 | F4: 945.4
A5: 40745 | B5: Singapore | C5: 670.6 | F5: 953.2
A6: 40752 | B6: Singapore | C6: 681.2 | F6: 958
A7: 40759 | B7: Singapore | C7: 674.7 | F7: 952.8
A8: 40766 | B8: Singapore | C8: 639.9 | F8: 894
A9: 40773 | B9: Singapore | C9: 648.8 | F9: 900.6
A10: 40780 | B10: Singapore | C10: 649.2 | F10: 900
A11: 40787 | B11: Singapore | C11: 663.4 | F11: 918.8
A12: 40794 | B12: Singapore | C12: 659.7 | F12: 922.6
A13: 40801 | B13: Singapore | C13: 653.2 | F13: 910.4
... A441: 43826 | B441: Singapore | C441: 371.55 | F441: 673.9
A442: 43833 | B442: Singapore | C442: 363.3 | D442: 723.7 | F442: 708.2 | G442: 712.6
A443: 43840 | B443: Singapore | C443: 393.3 | D443: 726.8 | F443: 734.9 | G443: 731
A444: 43847 | B444: Singapore | C444: 371 | D444: 670.8 | F444: 686.6 | G444: 677.4
A445: 43854 | B445: Singapore | C445: 367.1 | D445: 644.1 | F445: 651.1 | G445: 643
A446: 43861 | B446: Singapore | C446: 351.1 | D446: 594.1 | F446: 607.1 | G446: 592.6
A447: 43868 | B447: Singapore | C447: 324.6 | D447: 542.3 | F447: 554.9 | G447: 543.1
A448: 43875 | B448: Singapore | C448: 319.4 | D448: 520.7 | F448: 530 | G448: 522.9
A449: 43882 | B449: Singapore | C449: 323.5 | D449: 511 | F449: 524.9 | G449: 516.5
A450: 43889 | B450: Singapore | C450: 304.6 | D450: 458.8 | F450: 482.2 | G450: 470.4
A451: 43896 | B451: Singapore | C451: 296.6 | D451: 436.3 | F451: 453.9 | G451: 453.6
A452: 43903 | B452: Singapore | C452: 221.6 | D452: 340.9 | F452: 364.4 | G452: 359.9
A453: 43910 | B453: Singapore | C453: 202.4 | D453: 291.1 | F453: 306.1 | G453: 313.8
... A467: 44008 | B467: Singapore | C467: 253.1 | D467: 329.1 | F467: 376.3 | G467: 371.1

Sheet China n Importing Ports
A1: Port | B1: Date | C1: Unloading rate Handysize | D1: Unloading rate Supramax | E1: Unloading rate Panamax | F1: Unloading rate NeoPanamax | G1: Unloading rate Suezmax | H1: Unloading rate Capesize | I1: Unloading rate VLOC | J1: Currency | K1: RMB Fixed fee | L1: RMB per day berthed | M1: RMB per day anchored | N1: RMB/T_Cargo (wet) | O1: RMB/T_Cargo (wet)/day berthed | P1: RMB/T_Cargo (wet)/day anchored | Q1: RMB/NRT | R1: RMB/NRT/day berthed | S1: RMB/NRT/day anchored | T1: RMB/GRT | U1: RMB/GRT/day berthed | V1: RMB/GRT/day anchored | W1: RMB/LOA | X1: RMB/LOA/day berthed | Y1: RMB/LOA/day anchored | Z1: spare | AA1: spare | AB1: spare | AC1: spare | AD1: Comment
A2: Binzhou | B2: 43466 | C2: 42500 | D2: 42500 | E2: 42500 | F2: 42500 | G2: 42500 | H2: 42500 | I2: 42500 | J2: RMB | K2: 12342 | N2: 2.64 | Q2: 4.53 | R2: 0.367 | S2: 0.05 | W2: 197
A3: Caofeidian | B3: 43466 | C3: 42500 | D3: 42500 | E3: 42500 | F3: 42500 | G3: 42500 | H3: 42500 | I3: 42500 | J3: RMB | K3: 12342 | N3: 2.64 | Q3: 4.53 | R3: 0.367 | S3: 0.05 | W3: 197
A4: Fangchenggang | B4: 43466 | C4: 42500 | D4: 42500 | E4: 42500 | F4: 42500 | G4: 42500 | H4: 42500 | I4: 42500 | J4: RMB | K4: 12342 | N4: 2.64 | Q4: 4.53 | R4: 0.367 | S4: 0.05 | W4: 197
A5: Jingjiang | B5: 43466 | C5: 42500 | D5: 42500 | E5: 42500 | F5: 42500 | G5: 42500 | H5: 42500 | I5: 42500 | J5: RMB | K5: 12342 | N5: 2.64 | Q5: 4.53 | R5: 0.367 | S5: 0.05 | W5: 197
A6: Lianyungang | B6: 43466 | C6: 42500 | D6: 42500 | E6: 42500 | F6: 42500 | G6: 42500 | H6: 42500 | I6: 42500 | J6: RMB | K6: 12342 | N6: 2.64 | Q6: 4.53 | R6: 0.367 | S6: 0.05 | W6: 197
